Workbook

Sheet How to use
A1: How to use this workbook
A3: This workbook only displays status. Agents record progress in two small text files next to it
A4: (docs/sera-sync-v3-status.csv and docs/sera-sync-v3-checks.csv) using tools/sync_v3_tracker.py.
A5: You can keep this file open while agents work.
A7: To see the latest status: Data → Refresh All (Ctrl+Alt+F5). It also refreshes when opened and every minute.
A8: Don't type into the sheets: the next refresh overwrites it. To change a status, ask an agent or run the tool.
A9: When Excel asks to save on close, either answer is fine — the status lives in the CSV files, not here.
A11: What the agents record:
A12: • Implementing agent: Status = In progress + Model used when it starts; Status = In review + Notes when it finishes.
A13: • Reviewing agent (Fable 5.1 / Opus 5.5): Reviewed by.
A14: • Committing agent: Status = Done + Commit. The tool refuses Done without a commit, or without a required review.
A15: • The tool also refuses a model not allowed for the WP's tier, and starting a WP whose dependencies aren't Done.
... A23: If refresh ever shows an error about a missing file, the project folder moved: run the rebuild command.

Sheet Work Packages
A1: Sera Sync v3 — work packages
A2: Grey columns come from docs/sera-sync-v3-status.csv, which agents update with tools/sync_v3_tracker.py. Data → Refresh All (Ctrl+Alt+F5) to see the latest; it also refreshes on open and every minute. Don't type into this sheet: a refresh overwrites it.
A4: WP | B4: Phase | C4: What | D4: Tier | E4: Depends on | F4: Dependency note | G4: Review before merge | H4: Recommended Claude | I4: Gemini allowed | J4: Status | K4: Ready? | L4: Unfinished deps | M4: Model used | N4: Model allowed? | O4: Reviewed by | P4: Commit | Q4: Notes | R4: helper
A5: P0-1 | B5: 0 | C5: Stop sending the whole DB after every edit | D5: T1 | G5: No | H5: =INDEX(Models!$C$26:$C$28,MATCH(D5,Models!$A$26:$A$28,0)) -> Claude Haiku 4.5 | I5: =INDEX(Models!$D$26:$D$28,MATCH(D5,Models!$A$26:$A$28,0)) -> Any Gemini model on the Models sheet | J5: =IFERROR(IF(INDEX(StatusData!$B:$B,MATCH($A5,StatusData!$A:$A,0))="","Not started",""&INDEX(StatusData!$B:$B,MATCH($A5,StatusData!$A:$A,0))),"Not started") -> Done | K5: =IF(J5="Done","Done",IF(L5>0,"Waiting on "&L5,IF(J5="Not started","Ready",J5))) -> Done | L5: =IF(E5="",0,SUMPRODUCT(ISNUMBER(SEARCH(","&$A$5:$A$50&",",","&SUBSTITUTE(E5," ","")&","))*($J$5:$J$50<>"Done"))) -> 0 | M5: =IFERROR(""&INDEX(StatusData!$C:$C,MATCH($A5,StatusData!$A:$A,0)),"") -> Gemini 3.1 Pro | N5: =IF(M5="","",IFERROR(IF(INDEX(Models!$E$5:$G$19,MATCH(M5,Models!$A$5:$A$19,0),VALUE(RIGHT(D5,1)))="Yes","OK",IF(INDEX(Models!$E$5:$G$19,MATCH(M5,Models!$A$5:$A$19,0),VALUE(RIGHT(D5,1)))="Caution","Needs T3 review","NOT ALLOWED")),"Unknown model")) -> OK | O5: =IFERROR(""&INDEX(StatusData!$D:$D,MATCH($A5,StatusData!$A:$A,0)),"") -> Claude Opus 5.5 | P5: =IFERROR(""&INDEX(StatusData!$E:$E,MATCH($A5,StatusData!$A:$A,0)),"") -> df7a850 | Q5: =IFERROR(""&INDEX(StatusData!$F:$F,MATCH($A5,StatusData!$A:$A,0)),"") -> 2026-09-23: Re-reviewed fixes: applied timing bug fix, restored changelog | R5: =IF(K5="Ready",B5,"")
A6: P0-2 | B6: 0 | C6: Fix get_sync_metrics (is_deleted → is_archived) | D6: T1 | E6: P0-1 | F6: Must merge P0-1 first (see blueprint P0-2) | G6: No | H6: =INDEX(Models!$C$26:$C$28,MATCH(D6,Models!$A$26:$A$28,0)) -> Claude Haiku 4.5 | I6: =INDEX(Models!$D$26:$D$28,MATCH(D6,Models!$A$26:$A$28,0)) -> Any Gemini model on the Models sheet | J6: =IFERROR(IF(INDEX(StatusData!$B:$B,MATCH($A6,StatusData!$A:$A,0))="","Not started",""&INDEX(StatusData!$B:$B,MATCH($A6,StatusData!$A:$A,0))),"Not started") -> Done | K6: =IF(J6="Done","Done",IF(L6>0,"Waiting on "&L6,IF(J6="Not started","Ready",J6))) -> Done | L6: =IF(E6="",0,SUMPRODUCT(ISNUMBER(SEARCH(","&$A$5:$A$50&",",","&SUBSTITUTE(E6," ","")&","))*($J$5:$J$50<>"Done"))) -> 0 | M6: =IFERROR(""&INDEX(StatusData!$C:$C,MATCH($A6,StatusData!$A:$A,0)),"") -> Gemini 3.8 Flash | N6: =IF(M6="","",IFERROR(IF(INDEX(Models!$E$5:$G$19,MATCH(M6,Models!$A$5:$A$19,0),VALUE(RIGHT(D6,1)))="Yes","OK",IF(INDEX(Models!$E$5:$G$19,MATCH(M6,Models!$A$5:$A$19,0),VALUE(RIGHT(D6,1)))="Caution","Needs T3 review","NOT ALLOWED")),"Unknown model")) -> OK | O6: =IFERROR(""&INDEX(StatusData!$D:$D,MATCH($A6,StatusData!$A:$A,0)),"") -> Claude Opus 5.5 | P6: =IFERROR(""&INDEX(StatusData!$E:$E,MATCH($A6,StatusData!$A:$A,0)),"") -> 6d5051f | Q6: =IFERROR(""&INDEX(StatusData!$F:$F,MATCH($A6,StatusData!$A:$A,0)),"") -> 2026-09-23: Fixed get_sync_metrics is_archived check; 799 passed, 10 pre-existing failed | R6: =IF(K6="Ready",B6,"")
A7: P0-3 | B7: 0 | C7: Sender makes a consistent snapshot (sqlcipher_export) and streams it | D7: T2 | G7: Yes – Fable 5.1 / Opus 5.5 | H7: =INDEX(Models!$C$26:$C$28,MATCH(D7,Models!$A$26:$A$28,0)) -> Claude Sonnet 5 | I7: =INDEX(Models!$D$26:$D$28,MATCH(D7,Models!$A$26:$A$28,0)) -> Gemini 3.8 Flash, 3.1 Pro, 3.7 Flash (3.6 Flash / 3 Flash / 2.5 Pro only with review) | J7: =IFERROR(IF(INDEX(StatusData!$B:$B,MATCH($A7,StatusData!$A:$A,0))="","Not started",""&INDEX(StatusData!$B:$B,MATCH($A7,StatusData!$A:$A,0))),"Not started") -> Done | K7: =IF(J7="Done","Done",IF(L7>0,"Waiting on "&L7,IF(J7="Not started","Ready",J7))) -> Done | L7: =IF(E7="",0,SUMPRODUCT(ISNUMBER(SEARCH(","&$A$5:$A$50&",",","&SUBSTITUTE(E7," ","")&","))*($J$5:$J$50<>"Done"))) -> 0 | M7: =IFERROR(""&INDEX(StatusData!$C:$C,MATCH($A7,StatusData!$A:$A,0)),"") -> Gemini 3.8 Flash | N7: =IF(M7="","",IFERROR(IF(INDEX(Models!$E$5:$G$19,MATCH(M7,Models!$A$5:$A$19,0),VALUE(RIGHT(D7,1)))="Yes","OK",IF(INDEX(Models!$E$5:$G$19,MATCH(M7,Models!$A$5:$A$19,0),VALUE(RIGHT(D7,1)))="Caution","Needs T3 review","NOT ALLOWED")),"Unknown model")) -> OK | O7: =IFERROR(""&INDEX(StatusData!$D:$D,MATCH($A7,StatusData!$A:$A,0)),"") -> Claude Opus 5.5 | P7: =IFERROR(""&INDEX(StatusData!$E:$E,MATCH($A7,StatusData!$A:$A,0)),"") -> 6b38236 | Q7: =IFERROR(""&INDEX(StatusData!$F:$F,MATCH($A7,StatusData!$A:$A,0)),"") -> 2026-09-23: make_snapshot (FileExistsError guard) + 1MB stream + prune_outgoing_snapshots, 804 passed / 10 failed | R7: =IF(K7="Ready",B7,"")
A8: P0-4 | B8: 0 | C8: Receiver stages the DB and swaps it at start-up, never while running | D8: T2 | E8: P0-3 | G8: Yes – Fable 5.1 / Opus 5.5 | H8: =INDEX(Models!$C$26:$C$28,MATCH(D8,Models!$A$26:$A$28,0)) -> Claude Sonnet 5 | I8: =INDEX(Models!$D$26:$D$28,MATCH(D8,Models!$A$26:$A$28,0)) -> Gemini 3.8 Flash, 3.1 Pro, 3.7 Flash (3.6 Flash / 3 Flash / 2.5 Pro only with review) | J8: =IFERROR(IF(INDEX(StatusData!$B:$B,MATCH($A8,StatusData!$A:$A,0))="","Not started",""&INDEX(StatusData!$B:$B,MATCH($A8,StatusData!$A:$A,0))),"Not started") -> Done | K8: =IF(J8="Done","Done",IF(L8>0,"Waiting on "&L8,IF(J8="Not started","Ready",J8))) -> Done | L8: =IF(E8="",0,SUMPRODUCT(ISNUMBER(SEARCH(","&$A$5:$A$50&",",","&SUBSTITUTE(E8," ","")&","))*($J$5:$J$50<>"Done"))) -> 0 | M8: =IFERROR(""&INDEX(StatusData!$C:$C,MATCH($A8,StatusData!$A:$A,0)),"") -> Gemini 3.8 Flash | N8: =IF(M8="","",IFERROR(IF(INDEX(Models!$E$5:$G$19,MATCH(M8,Models!$A$5:$A$19,0),VALUE(RIGHT(D8,1)))="Yes","OK",IF(INDEX(Models!$E$5:$G$19,MATCH(M8,Models!$A$5:$A$19,0),VALUE(RIGHT(D8,1)))="Caution","Needs T3 review","NOT ALLOWED")),"Unknown model")) -> OK | O8: =IFERROR(""&INDEX(StatusData!$D:$D,MATCH($A8,StatusData!$A:$A,0)),"") -> Claude Opus 5.5 | P8: =IFERROR(""&INDEX(StatusData!$E:$E,MATCH($A8,StatusData!$A:$A,0)),"") -> 89c9aa3 | Q8: =IFERROR(""&INDEX(StatusData!$F:$F,MATCH($A8,StatusData!$A:$A,0)),"") -> 2026-09-24: Fixed rollback WAL/SHM restoration on failed DB replace; closed RESTART_PENDING concurrency gap; 18/18 hotfix, 10/10 sync passed | R8: =IF(K8="Ready",B8,"")
A9: P0-5 | B9: 0 | C9: Start-up checks that sera.key opens the DB; prompts otherwise | D9: T2 | G9: No | H9: =INDEX(Models!$C$26:$C$28,MATCH(D9,Models!$A$26:$A$28,0)) -> Claude Sonnet 5 | I9: =INDEX(Models!$D$26:$D$28,MATCH(D9,Models!$A$26:$A$28,0)) -> Gemini 3.8 Flash, 3.1 Pro, 3.7 Flash (3.6 Flash / 3 Flash / 2.5 Pro only with review) | J9: =IFERROR(IF(INDEX(StatusData!$B:$B,MATCH($A9,StatusData!$A:$A,0))="","Not started",""&INDEX(StatusData!$B:$B,MATCH($A9,StatusData!$A:$A,0))),"Not started") -> Done | K9: =IF(J9="Done","Done",IF(L9>0,"Waiting on "&L9,IF(J9="Not started","Ready",J9))) -> Done | L9: =IF(E9="",0,SUMPRODUCT(ISNUMBER(SEARCH(","&$A$5:$A$50&",",","&SUBSTITUTE(E9," ","")&","))*($J$5:$J$50<>"Done"))) -> 0 | M9: =IFERROR(""&INDEX(StatusData!$C:$C,MATCH($A9,StatusData!$A:$A,0)),"") -> Gemini 3.8 Flash | N9: =IF(M9="","",IFERROR(IF(INDEX(Models!$E$5:$G$19,MATCH(M9,Models!$A$5:$A$19,0),VALUE(RIGHT(D9,1)))="Yes","OK",IF(INDEX(Models!$E$5:$G$19,MATCH(M9,Models!$A$5:$A$19,0),VALUE(RIGHT(D9,1)))="Caution","Needs T3 review","NOT ALLOWED")),"Unknown model")) -> OK | O9: =IFERROR(""&INDEX(StatusData!$D:$D,MATCH($A9,StatusData!$A:$A,0)),"") -> Claude Opus 5.5 | P9: =IFERROR(""&INDEX(StatusData!$E:$E,MATCH($A9,StatusData!$A:$A,0)),"") -> 487d6bf | Q9: =IFERROR(""&INDEX(StatusData!$F:$F,MATCH($A9,StatusData!$A:$A,0)),"") -> 2026-09-24: Startup password check, 3-try prompt, failure modal, salt guard, 815 passed / 10 failed. Opus 5.5 review follow-ups done (damaged-DB wording, deviations logged). Don't release before P0-6. | R9: =IF(K9="Ready",B9,"")
A10: P0-6 | B10: 0 | C10: First-run "New office / Join office" + legacy join with on-screen approval | D10: T2 | E10: P0-3,P0-4,P0-5 | G10: Yes – Fable 5.1 / Opus 5.5 | H10: =INDEX(Models!$C$26:$C$28,MATCH(D10,Models!$A$26:$A$28,0)) -> Claude Sonnet 5 | I10: =INDEX(Models!$D$26:$D$28,MATCH(D10,Models!$A$26:$A$28,0)) -> Gemini 3.8 Flash, 3.1 Pro, 3.7 Flash (3.6 Flash / 3 Flash / 2.5 Pro only with review) | J10: =IFERROR(IF(INDEX(StatusData!$B:$B,MATCH($A10,StatusData!$A:$A,0))="","Not started",""&INDEX(StatusData!$B:$B,MATCH($A10,StatusData!$A:$A,0))),"Not started") -> Done | K10: =IF(J10="Done","Done",IF(L10>0,"Waiting on "&L10,IF(J10="Not started","Ready",J10))) -> Done | L10: =IF(E10="",0,SUMPRODUCT(ISNUMBER(SEARCH(","&$A$5:$A$50&",",","&SUBSTITUTE(E10," ","")&","))*($J$5:$J$50<>"Done"))) -> 0 | M10: =IFERROR(""&INDEX(StatusData!$C:$C,MATCH($A10,StatusData!$A:$A,0)),"") -> Gemini 3.8 Flash | N10: =IF(M10="","",IFERROR(IF(INDEX(Models!$E$5:$G$19,MATCH(M10,Models!$A$5:$A$19,0),VALUE(RIGHT(D10,1)))="Yes","OK",IF(INDEX(Models!$E$5:$G$19,MATCH(M10,Models!$A$5:$A$19,0),VALUE(RIGHT(D10,1)))="Caution","Needs T3 review","NOT ALLOWED")),"Unknown model")) -> OK | O10: =IFERROR(""&INDEX(StatusData!$D:$D,MATCH($A10,StatusData!$A:$A,0)),"") -> Claude Opus 5.5 | P10: =IFERROR(""&INDEX(StatusData!$E:$E,MATCH($A10,StatusData!$A:$A,0)),"") -> 832b053 | Q10: =IFERROR(""&INDEX(StatusData!$F:$F,MATCH($A10,StatusData!$A:$A,0)),"") -> 2026-09-24: First-run New/Join office with on-screen modal approval, snapshot streaming, password verification, 7 new tests passed (837/10) | R10: =IF(K10="Ready",B10,"")
A11: P0-7 | B11: 0 | C11: Authenticate legacy sync messages (HMAC) | D11: T2 | E11: P0-6 | G11: Yes – Fable 5.1 / Opus 5.5 | H11: =INDEX(Models!$C$26:$C$28,MATCH(D11,Models!$A$26:$A$28,0)) -> Claude Sonnet 5 | I11: =INDEX(Models!$D$26:$D$28,MATCH(D11,Models!$A$26:$A$28,0)) -> Gemini 3.8 Flash, 3.1 Pro, 3.7 Flash (3.6 Flash / 3 Flash / 2.5 Pro only with review) | J11: =IFERROR(IF(INDEX(StatusData!$B:$B,MATCH($A11,StatusData!$A:$A,0))="","Not started",""&INDEX(StatusData!$B:$B,MATCH($A11,StatusData!$A:$A,0))),"Not started") -> Done | K11: =IF(J11="Done","Done",IF(L11>0,"Waiting on "&L11,IF(J11="Not started","Ready",J11))) -> Done | L11: =IF(E11="",0,SUMPRODUCT(ISNUMBER(SEARCH(","&$A$5:$A$50&",",","&SUBSTITUTE(E11," ","")&","))*($J$5:$J$50<>"Done"))) -> 0 | M11: =IFERROR(""&INDEX(StatusData!$C:$C,MATCH($A11,StatusData!$A:$A,0)),"") -> Claude Sonnet 5 | N11: =IF(M11="","",IFERROR(IF(INDEX(Models!$E$5:$G$19,MATCH(M11,Models!$A$5:$A$19,0),VALUE(RIGHT(D11,1)))="Yes","OK",IF(INDEX(Models!$E$5:$G$19,MATCH(M11,Models!$A$5:$A$19,0),VALUE(RIGHT(D11,1)))="Caution","Needs T3 review","NOT ALLOWED")),"Unknown model")) -> OK | O11: =IFERROR(""&INDEX(StatusData!$D:$D,MATCH($A11,StatusData!$A:$A,0)),"") -> Claude Opus 5.5 | P11: =IFERROR(""&INDEX(StatusData!$E:$E,MATCH($A11,StatusData!$A:$A,0)),"") -> 89d7cfc | Q11: =IFERROR(""&INDEX(StatusData!$F:$F,MATCH($A11,StatusData!$A:$A,0)),"") -> 2026-09-24: HMAC auth as before, plus a rollout-compatibility follow-up: rejection of a pre-P0-7 peer now carries an advisory hint (reason unchanged) and §6/§7 document the simultaneous-upgrade requirement. | R11: =IF(K11="Ready",B11,"")
A12: P0-8 | B12: 0 | C12: rawPayload.db auto-heal: visible alert + audit entry | D12: T1 | G12: No | H12: =INDEX(Models!$C$26:$C$28,MATCH(D12,Models!$A$26:$A$28,0)) -> Claude Haiku 4.5 | I12: =INDEX(Models!$D$26:$D$28,MATCH(D12,Models!$A$26:$A$28,0)) -> Any Gemini model on the Models sheet | J12: =IFERROR(IF(INDEX(StatusData!$B:$B,MATCH($A12,StatusData!$A:$A,0))="","Not started",""&INDEX(StatusData!$B:$B,MATCH($A12,StatusData!$A:$A,0))),"Not started") -> Done | K12: =IF(J12="Done","Done",IF(L12>0,"Waiting on "&L12,IF(J12="Not started","Ready",J12))) -> Done | L12: =IF(E12="",0,SUMPRODUCT(ISNUMBER(SEARCH(","&$A$5:$A$50&",",","&SUBSTITUTE(E12," ","")&","))*($J$5:$J$50<>"Done"))) -> 0 | M12: =IFERROR(""&INDEX(StatusData!$C:$C,MATCH($A12,StatusData!$A:$A,0)),"") -> Claude Haiku 4.5 | N12: =IF(M12="","",IFERROR(IF(INDEX(Models!$E$5:$G$19,MATCH(M12,Models!$A$5:$A$19,0),VALUE(RIGHT(D12,1)))="Yes","OK",IF(INDEX(Models!$E$5:$G$19,MATCH(M12,Models!$A$5:$A$19,0),VALUE(RIGHT(D12,1)))="Caution","Needs T3 review","NOT ALLOWED")),"Unknown model")) -> OK | O12: =IFERROR(""&INDEX(StatusData!$D:$D,MATCH($A12,StatusData!$A:$A,0)),"") -> Claude Opus 5.5 | P12: =IFERROR(""&INDEX(StatusData!$E:$E,MATCH($A12,StatusData!$A:$A,0)),"") -> 7250dd4 | Q12: =IFERROR(""&INDEX(StatusData!$F:$F,MATCH($A12,StatusData!$A:$A,0)),"") -> 2026-09-23: Added raw_db_was_reset tracking, audit log entry, and UI alert when auto-heal occurs. Test passes, no deviations from spec. | R12: =IF(K12="Ready",B12,"")
A13: P0-9a | B13: 0 | C13: Installer firewall rules (Private + Domain + Public, v1.4) | D13: T1 | G13: No | H13: =INDEX(Models!$C$26:$C$28,MATCH(D13,Models!$A$26:$A$28,0)) -> Claude Haiku 4.5 | I13: =INDEX(Models!$D$26:$D$28,MATCH(D13,Models!$A$26:$A$28,0)) -> Any Gemini model on the Models sheet | J13: =IFERROR(IF(INDEX(StatusData!$B:$B,MATCH($A13,StatusData!$A:$A,0))="","Not started",""&INDEX(StatusData!$B:$B,MATCH($A13,StatusData!$A:$A,0))),"Not started") -> Done | K13: =IF(J13="Done","Done",IF(L13>0,"Waiting on "&L13,IF(J13="Not started","Ready",J13))) -> Done | L13: =IF(E13="",0,SUMPRODUCT(ISNUMBER(SEARCH(","&$A$5:$A$50&",",","&SUBSTITUTE(E13," ","")&","))*($J$5:$J$50<>"Done"))) -> 0 | M13: =IFERROR(""&INDEX(StatusData!$C:$C,MATCH($A13,StatusData!$A:$A,0)),"") -> Gemini 3.8 Flash | N13: =IF(M13="","",IFERROR(IF(INDEX(Models!$E$5:$G$19,MATCH(M13,Models!$A$5:$A$19,0),VALUE(RIGHT(D13,1)))="Yes","OK",IF(INDEX(Models!$E$5:$G$19,MATCH(M13,Models!$A$5:$A$19,0),VALUE(RIGHT(D13,1)))="Caution","Needs T3 review","NOT ALLOWED")),"Unknown model")) -> OK | O13: =IFERROR(""&INDEX(StatusData!$D:$D,MATCH($A13,StatusData!$A:$A,0)),"") -> Claude Opus 5.5 | P13: =IFERROR(""&INDEX(StatusData!$E:$E,MATCH($A13,StatusData!$A:$A,0)),"") -> faa61d6 | Q13: =IFERROR(""&INDEX(StatusData!$F:$F,MATCH($A13,StatusData!$A:$A,0)),"") -> 2026-09-24: Installer firewall rules added with pre-emptive delete on upgrade and RunOnceId; test_installer_firewall_rules passed | R13: =IF(K13="Ready",B13,"")
A14: P0-9b | B14: 0 | C14: In-app warning when the network profile is Public | D14: T2 | G14: No | H14: =INDEX(Models!$C$26:$C$28,MATCH(D14,Models!$A$26:$A$28,0)) -> Claude Sonnet 5 | I14: =INDEX(Models!$D$26:$D$28,MATCH(D14,Models!$A$26:$A$28,0)) -> Gemini 3.8 Flash, 3.1 Pro, 3.7 Flash (3.6 Flash / 3 Flash / 2.5 Pro only with review) | J14: =IFERROR(IF(INDEX(StatusData!$B:$B,MATCH($A14,StatusData!$A:$A,0))="","Not started",""&INDEX(StatusData!$B:$B,MATCH($A14,StatusData!$A:$A,0))),"Not started") -> Done | K14: =IF(J14="Done","Done",IF(L14>0,"Waiting on "&L14,IF(J14="Not started","Ready",J14))) -> Done | L14: =IF(E14="",0,SUMPRODUCT(ISNUMBER(SEARCH(","&$A$5:$A$50&",",","&SUBSTITUTE(E14," ","")&","))*($J$5:$J$50<>"Done"))) -> 0 | M14: =IFERROR(""&INDEX(StatusData!$C:$C,MATCH($A14,StatusData!$A:$A,0)),"") -> Claude Sonnet 5 | N14: =IF(M14="","",IFERROR(IF(INDEX(Models!$E$5:$G$19,MATCH(M14,Models!$A$5:$A$19,0),VALUE(RIGHT(D14,1)))="Yes","OK",IF(INDEX(Models!$E$5:$G$19,MATCH(M14,Models!$A$5:$A$19,0),VALUE(RIGHT(D14,1)))="Caution","Needs T3 review","NOT ALLOWED")),"Unknown model")) -> OK | O14: =IFERROR(""&INDEX(StatusData!$D:$D,MATCH($A14,StatusData!$A:$A,0)),"") -> Claude Opus 5.5 | P14: =IFERROR(""&INDEX(StatusData!$E:$E,MATCH($A14,StatusData!$A:$A,0)),"") -> 214a7a9 | Q14: =IFERROR(""&INDEX(StatusData!$F:$F,MATCH($A14,StatusData!$A:$A,0)),"") -> 2026-09-24: Fixed reviewer bug #2 (PowerShell numeric NetworkCategory, verified live on Public hotspot); could not reproduce bug #1 (no enable_network_monitor flag exists in current tree); applied 4 hardening items. Full suite: 839 passed/10 failed (all pre-existing). | R14: =IF(K14="Ready",B14,"")
A15: P0-10 | B15: 0 | C15: Per-adapter broadcast, "Add PC by IP", peers keyed by host | D15: T2 | G15: No | H15: =INDEX(Models!$C$26:$C$28,MATCH(D15,Models!$A$26:$A$28,0)) -> Claude Sonnet 5 | I15: =INDEX(Models!$D$26:$D$28,MATCH(D15,Models!$A$26:$A$28,0)) -> Gemini 3.8 Flash, 3.1 Pro, 3.7 Flash (3.6 Flash / 3 Flash / 2.5 Pro only with review) | J15: =IFERROR(IF(INDEX(StatusData!$B:$B,MATCH($A15,StatusData!$A:$A,0))="","Not started",""&INDEX(StatusData!$B:$B,MATCH($A15,StatusData!$A:$A,0))),"Not started") -> Done | K15: =IF(J15="Done","Done",IF(L15>0,"Waiting on "&L15,IF(J15="Not started","Ready",J15))) -> Done | L15: =IF(E15="",0,SUMPRODUCT(ISNUMBER(SEARCH(","&$A$5:$A$50&",",","&SUBSTITUTE(E15," ","")&","))*($J$5:$J$50<>"Done"))) -> 0 | M15: =IFERROR(""&INDEX(StatusData!$C:$C,MATCH($A15,StatusData!$A:$A,0)),"") -> Gemini 3.8 Flash | N15: =IF(M15="","",IFERROR(IF(INDEX(Models!$E$5:$G$19,MATCH(M15,Models!$A$5:$A$19,0),VALUE(RIGHT(D15,1)))="Yes","OK",IF(INDEX(Models!$E$5:$G$19,MATCH(M15,Models!$A$5:$A$19,0),VALUE(RIGHT(D15,1)))="Caution","Needs T3 review","NOT ALLOWED")),"Unknown model")) -> OK | O15: =IFERROR(""&INDEX(StatusData!$D:$D,MATCH($A15,StatusData!$A:$A,0)),"") -> Claude Opus 5.5 | P15: =IFERROR(""&INDEX(StatusData!$E:$E,MATCH($A15,StatusData!$A:$A,0)),"") -> 66feefe | Q15: =IFERROR(""&INDEX(StatusData!$F:$F,MATCH($A15,StatusData!$A:$A,0)),"") -> 2026-09-24: Review fixes: 10s beacon interval (anti-flap), port 1-65535 validation, per-peer exception isolation, listener guard, rate-limited replies | R15: =IF(K15="Ready",B15,"")
A16: P0-11 | B16: 0 | C16: Docs: operations-sync.md update | D16: T1 | E16: P0-1,P0-10 | G16: No | H16: =INDEX(Models!$C$26:$C$28,MATCH(D16,Models!$A$26:$A$28,0)) -> Claude Haiku 4.5 | I16: =INDEX(Models!$D$26:$D$28,MATCH(D16,Models!$A$26:$A$28,0)) -> Any Gemini model on the Models sheet | J16: =IFERROR(IF(INDEX(StatusData!$B:$B,MATCH($A16,StatusData!$A:$A,0))="","Not started",""&INDEX(StatusData!$B:$B,MATCH($A16,StatusData!$A:$A,0))),"Not started") -> Done | K16: =IF(J16="Done","Done",IF(L16>0,"Waiting on "&L16,IF(J16="Not started","Ready",J16))) -> Done | L16: =IF(E16="",0,SUMPRODUCT(ISNUMBER(SEARCH(","&$A$5:$A$50&",",","&SUBSTITUTE(E16," ","")&","))*($J$5:$J$50<>"Done"))) -> 0 | M16: =IFERROR(""&INDEX(StatusData!$C:$C,MATCH($A16,StatusData!$A:$A,0)),"") -> Gemini 3.7 Flash | N16: =IF(M16="","",IFERROR(IF(INDEX(Models!$E$5:$G$19,MATCH(M16,Models!$A$5:$A$19,0),VALUE(RIGHT(D16,1)))="Yes","OK",IF(INDEX(Models!$E$5:$G$19,MATCH(M16,Models!$A$5:$A$19,0),VALUE(RIGHT(D16,1)))="Caution","Needs T3 review","NOT ALLOWED")),"Unknown model")) -> OK | O16: =IFERROR(""&INDEX(StatusData!$D:$D,MATCH($A16,StatusData!$A:$A,0)),"") | P16: =IFERROR(""&INDEX(StatusData!$E:$E,MATCH($A16,StatusData!$A:$A,0)),"") -> 60667de | Q16: =IFERROR(""&INDEX(StatusData!$F:$F,MATCH($A16,StatusData!$A:$A,0)),"") -> 2026-09-24: docs/operations-sync.md updated for Phase 0, full test suite 859 passed / 10 pre-existing failed | R16: =IF(K16="Ready",B16,"")
A17: P1-1 | B17: 1 | C17: sera_keys.py: DPAPI, office.json, key id, recovery blob | D17: T3 | E17: P0-1,P0-2,P0-3,P0-4,P0-5,P0-6,P0-7,P0-8,P0-9a,P0-9b,P0-10,P0-11 | F17: Phase 0 released to all PCs | G17: Yes – Fable 5.1 / Opus 5.5 | H17: =INDEX(Models!$C$26:$C$28,MATCH(D17,Models!$A$26:$A$28,0)) -> Claude Fable 5.1 or Opus 5.5 | I17: =INDEX(Models!$D$26:$D$28,MATCH(D17,Models!$A$26:$A$28,0)) -> Not allowed (owner decision) | J17: =IFERROR(IF(INDEX(StatusData!$B:$B,MATCH($A17,StatusData!$A:$A,0))="","Not started",""&INDEX(StatusData!$B:$B,MATCH($A17,StatusData!$A:$A,0))),"Not started") -> Done | K17: =IF(J17="Done","Done",IF(L17>0,"Waiting on "&L17,IF(J17="Not started","Ready",J17))) -> Done | L17: =IF(E17="",0,SUMPRODUCT(ISNUMBER(SEARCH(","&$A$5:$A$50&",",","&SUBSTITUTE(E17," ","")&","))*($J$5:$J$50<>"Done"))) -> 0 | M17: =IFERROR(""&INDEX(StatusData!$C:$C,MATCH($A17,StatusData!$A:$A,0)),"") -> Claude Opus 5.5 | N17: =IF(M17="","",IFERROR(IF(INDEX(Models!$E$5:$G$19,MATCH(M17,Models!$A$5:$A$19,0),VALUE(RIGHT(D17,1)))="Yes","OK",IF(INDEX(Models!$E$5:$G$19,MATCH(M17,Models!$A$5:$A$19,0),VALUE(RIGHT(D17,1)))="Caution","Needs T3 review","NOT ALLOWED")),"Unknown model")) -> OK | O17: =IFERROR(""&INDEX(StatusData!$D:$D,MATCH($A17,StatusData!$A:$A,0)),"") -> Claude Opus 5.5 | P17: =IFERROR(""&INDEX(StatusData!$E:$E,MATCH($A17,StatusData!$A:$A,0)),"") -> 773eea7 | Q17: =IFERROR(""&INDEX(StatusData!$F:$F,MATCH($A17,StatusData!$A:$A,0)),"") -> 2026-09-24: New sera_keys.py (DPAPI ctypes, Argon2id+AES-GCM wrap, office.json, key id, store/load/recover DEK) + tests/test_sera_keys.py (24); full suite 883 passed / 10 pre-existing failures | R17: =IF(K17="Ready",B17,"")
A18: P1-2 | B18: 1 | C18: Start-up key resolution (office mode / legacy mode) | D18: T2 | E18: P1-1 | G18: No | H18: =INDEX(Models!$C$26:$C$28,MATCH(D18,Models!$A$26:$A$28,0)) -> Claude Sonnet 5 | I18: =INDEX(Models!$D$26:$D$28,MATCH(D18,Models!$A$26:$A$28,0)) -> Gemini 3.8 Flash, 3.1 Pro, 3.7 Flash (3.6 Flash / 3 Flash / 2.5 Pro only with review) | J18: =IFERROR(IF(INDEX(StatusData!$B:$B,MATCH($A18,StatusData!$A:$A,0))="","Not started",""&INDEX(StatusData!$B:$B,MATCH($A18,StatusData!$A:$A,0))),"Not started") -> Done | K18: =IF(J18="Done","Done",IF(L18>0,"Waiting on "&L18,IF(J18="Not started","Ready",J18))) -> Done | L18: =IF(E18="",0,SUMPRODUCT(ISNUMBER(SEARCH(","&$A$5:$A$50&",",","&SUBSTITUTE(E18," ","")&","))*($J$5:$J$50<>"Done"))) -> 0 | M18: =IFERROR(""&INDEX(StatusData!$C:$C,MATCH($A18,StatusData!$A:$A,0)),"") -> Gemini 3.8 Flash | N18: =IF(M18="","",IFERROR(IF(INDEX(Models!$E$5:$G$19,MATCH(M18,Models!$A$5:$A$19,0),VALUE(RIGHT(D18,1)))="Yes","OK",IF(INDEX(Models!$E$5:$G$19,MATCH(M18,Models!$A$5:$A$19,0),VALUE(RIGHT(D18,1)))="Caution","Needs T3 review","NOT ALLOWED")),"Unknown model")) -> OK | O18: =IFERROR(""&INDEX(StatusData!$D:$D,MATCH($A18,StatusData!$A:$A,0)),"") -> Claude Opus 5.5 | P18: =IFERROR(""&INDEX(StatusData!$E:$E,MATCH($A18,StatusData!$A:$A,0)),"") -> 7808f87 | Q18: =IFERROR(""&INDEX(StatusData!$F:$F,MATCH($A18,StatusData!$A:$A,0)),"") -> 2026-09-24: Start-up key resolution (office mode DEK vs legacy PBKDF2), 889 passed / 10 pre-existing failed | R18: =IF(K18="Ready",B18,"")
A19: P1-3 | B19: 1 | C19: Parsers load the key through sera_keys | D19: T1 | E19: P1-2 | G19: No | H19: =INDEX(Models!$C$26:$C$28,MATCH(D19,Models!$A$26:$A$28,0)) -> Claude Haiku 4.5 | I19: =INDEX(Models!$D$26:$D$28,MATCH(D19,Models!$A$26:$A$28,0)) -> Any Gemini model on the Models sheet | J19: =IFERROR(IF(INDEX(StatusData!$B:$B,MATCH($A19,StatusData!$A:$A,0))="","Not started",""&INDEX(StatusData!$B:$B,MATCH($A19,StatusData!$A:$A,0))),"Not started") -> Done | K19: =IF(J19="Done","Done",IF(L19>0,"Waiting on "&L19,IF(J19="Not started","Ready",J19))) -> Done | L19: =IF(E19="",0,SUMPRODUCT(ISNUMBER(SEARCH(","&$A$5:$A$50&",",","&SUBSTITUTE(E19," ","")&","))*($J$5:$J$50<>"Done"))) -> 0 | M19: =IFERROR(""&INDEX(StatusData!$C:$C,MATCH($A19,StatusData!$A:$A,0)),"") -> Claude Sonnet 5 | N19: =IF(M19="","",IFERROR(IF(INDEX(Models!$E$5:$G$19,MATCH(M19,Models!$A$5:$A$19,0),VALUE(RIGHT(D19,1)))="Yes","OK",IF(INDEX(Models!$E$5:$G$19,MATCH(M19,Models!$A$5:$A$19,0),VALUE(RIGHT(D19,1)))="Caution","Needs T3 review","NOT ALLOWED")),"Unknown model")) -> OK | O19: =IFERROR(""&INDEX(StatusData!$D:$D,MATCH($A19,StatusData!$A:$A,0)),"") | P19: =IFERROR(""&INDEX(StatusData!$E:$E,MATCH($A19,StatusData!$A:$A,0)),"") -> bb80c15 | Q19: =IFERROR(""&INDEX(StatusData!$F:$F,MATCH($A19,StatusData!$A:$A,0)),"") -> 2026-09-24: Parsers try sera_keys office DEK (data dir then code dir) before legacy sera.key/salt. Full suite 891 passed / 10 pre-existing failed. | R19: =IF(K19="Ready",B19,"")
A20: P1-4 | B20: 1 | C20: Migration "convert this PC to an office key" | D20: T3 | E20: P1-2 | G20: Yes – Fable 5.1 / Opus 5.5 | H20: =INDEX(Models!$C$26:$C$28,MATCH(D20,Models!$A$26:$A$28,0)) -> Claude Fable 5.1 or Opus 5.5 | I20: =INDEX(Models!$D$26:$D$28,MATCH(D20,Models!$A$26:$A$28,0)) -> Not allowed (owner decision) | J20: =IFERROR(IF(INDEX(StatusData!$B:$B,MATCH($A20,StatusData!$A:$A,0))="","Not started",""&INDEX(StatusData!$B:$B,MATCH($A20,StatusData!$A:$A,0))),"Not started") -> Done | K20: =IF(J20="Done","Done",IF(L20>0,"Waiting on "&L20,IF(J20="Not started","Ready",J20))) -> Done | L20: =IF(E20="",0,SUMPRODUCT(ISNUMBER(SEARCH(","&$A$5:$A$50&",",","&SUBSTITUTE(E20," ","")&","))*($J$5:$J$50<>"Done"))) -> 0 | M20: =IFERROR(""&INDEX(StatusData!$C:$C,MATCH($A20,StatusData!$A:$A,0)),"") -> Claude Opus 5.5 | N20: =IF(M20="","",IFERROR(IF(INDEX(Models!$E$5:$G$19,MATCH(M20,Models!$A$5:$A$19,0),VALUE(RIGHT(D20,1)))="Yes","OK",IF(INDEX(Models!$E$5:$G$19,MATCH(M20,Models!$A$5:$A$19,0),VALUE(RIGHT(D20,1)))="Caution","Needs T3 review","NOT ALLOWED")),"Unknown model")) -> OK | O20: =IFERROR(""&INDEX(StatusData!$D:$D,MATCH($A20,StatusData!$A:$A,0)),"") -> Claude Opus 5.5 | P20: =IFERROR(""&INDEX(StatusData!$E:$E,MATCH($A20,StatusData!$A:$A,0)),"") -> c6bcc11 | Q20: =IFERROR(""&INDEX(StatusData!$F:$F,MATCH($A20,StatusData!$A:$A,0)),"") -> 2026-09-24: Review round 2: live-DB check refuses missing/empty file; step-6 rollback crash resumes as rollback (phase rolling_back); 28 tests; suite 936 passed / 10 pre-existing failures | R20: =IF(K20="Ready",B20,"")
A21: P1-5 | B21: 1 | C21: Key-fingerprint gate everywhere | D21: T2 | E21: P1-2 | G21: No | H21: =INDEX(Models!$C$26:$C$28,MATCH(D21,Models!$A$26:$A$28,0)) -> Claude Sonnet 5 | I21: =INDEX(Models!$D$26:$D$28,MATCH(D21,Models!$A$26:$A$28,0)) -> Gemini 3.8 Flash, 3.1 Pro, 3.7 Flash (3.6 Flash / 3 Flash / 2.5 Pro only with review) | J21: =IFERROR(IF(INDEX(StatusData!$B:$B,MATCH($A21,StatusData!$A:$A,0))="","Not started",""&INDEX(StatusData!$B:$B,MATCH($A21,StatusData!$A:$A,0))),"Not started") -> Done | K21: =IF(J21="Done","Done",IF(L21>0,"Waiting on "&L21,IF(J21="Not started","Ready",J21))) -> Done | L21: =IF(E21="",0,SUMPRODUCT(ISNUMBER(SEARCH(","&$A$5:$A$50&",",","&SUBSTITUTE(E21," ","")&","))*($J$5:$J$50<>"Done"))) -> 0 | M21: =IFERROR(""&INDEX(StatusData!$C:$C,MATCH($A21,StatusData!$A:$A,0)),"") -> Gemini 3.8 Flash | N21: =IF(M21="","",IFERROR(IF(INDEX(Models!$E$5:$G$19,MATCH(M21,Models!$A$5:$A$19,0),VALUE(RIGHT(D21,1)))="Yes","OK",IF(INDEX(Models!$E$5:$G$19,MATCH(M21,Models!$A$5:$A$19,0),VALUE(RIGHT(D21,1)))="Caution","Needs T3 review","NOT ALLOWED")),"Unknown model")) -> OK | O21: =IFERROR(""&INDEX(StatusData!$D:$D,MATCH($A21,StatusData!$A:$A,0)),"") -> Claude Opus 5.5 | P21: =IFERROR(""&INDEX(StatusData!$E:$E,MATCH($A21,StatusData!$A:$A,0)),"") -> 1960b19 | Q21: =IFERROR(""&INDEX(StatusData!$F:$F,MATCH($A21,StatusData!$A:$A,0)),"") -> 2026-09-24: Review fixes: zero-salt framing, legacy fetch_snapshot gated, salt backup; 937 passed / 10 failed | R21: =IF(K21="Ready",B21,"")
A22: P1-6 | B22: 1 | C22: Recovery, recovery kit export, master-password change | D22: T2 | E22: P1-1 | G22: Yes – Fable 5.1 / Opus 5.5 | H22: =INDEX(Models!$C$26:$C$28,MATCH(D22,Models!$A$26:$A$28,0)) -> Claude Sonnet 5 | I22: =INDEX(Models!$D$26:$D$28,MATCH(D22,Models!$A$26:$A$28,0)) -> Gemini 3.8 Flash, 3.1 Pro, 3.7 Flash (3.6 Flash / 3 Flash / 2.5 Pro only with review) | J22: =IFERROR(IF(INDEX(StatusData!$B:$B,MATCH($A22,StatusData!$A:$A,0))="","Not started",""&INDEX(StatusData!$B:$B,MATCH($A22,StatusData!$A:$A,0))),"Not started") -> Done | K22: =IF(J22="Done","Done",IF(L22>0,"Waiting on "&L22,IF(J22="Not started","Ready",J22))) -> Done | L22: =IF(E22="",0,SUMPRODUCT(ISNUMBER(SEARCH(","&$A$5:$A$50&",",","&SUBSTITUTE(E22," ","")&","))*($J$5:$J$50<>"Done"))) -> 0 | M22: =IFERROR(""&INDEX(StatusData!$C:$C,MATCH($A22,StatusData!$A:$A,0)),"") -> Gemini 3.8 Flash | N22: =IF(M22="","",IFERROR(IF(INDEX(Models!$E$5:$G$19,MATCH(M22,Models!$A$5:$A$19,0),VALUE(RIGHT(D22,1)))="Yes","OK",IF(INDEX(Models!$E$5:$G$19,MATCH(M22,Models!$A$5:$A$19,0),VALUE(RIGHT(D22,1)))="Caution","Needs T3 review","NOT ALLOWED")),"Unknown model")) -> OK | O22: =IFERROR(""&INDEX(StatusData!$D:$D,MATCH($A22,StatusData!$A:$A,0)),"") -> Claude Opus 5.5 | P22: =IFERROR(""&INDEX(StatusData!$E:$E,MATCH($A22,StatusData!$A:$A,0)),"") -> 79149ab | Q22: =IFERROR(""&INDEX(StatusData!$F:$F,MATCH($A22,StatusData!$A:$A,0)),"") -> 2026-09-24: Review blockers A and B resolved: settings backup page fixed, exact whitespace preserved with lenient fallback, full suite clean | R22: =IF(K22="Ready",B22,"")
A23: P2-1 | B23: 2 | C23: Device identity + certificates | D23: T2 | E23: P1-1 | G23: Yes – Fable 5.1 / Opus 5.5 | H23: =INDEX(Models!$C$26:$C$28,MATCH(D23,Models!$A$26:$A$28,0)) -> Claude Sonnet 5 | I23: =INDEX(Models!$D$26:$D$28,MATCH(D23,Models!$A$26:$A$28,0)) -> Gemini 3.8 Flash, 3.1 Pro, 3.7 Flash (3.6 Flash / 3 Flash / 2.5 Pro only with review) | J23: =IFERROR(IF(INDEX(StatusData!$B:$B,MATCH($A23,StatusData!$A:$A,0))="","Not started",""&INDEX(StatusData!$B:$B,MATCH($A23,StatusData!$A:$A,0))),"Not started") -> Done | K23: =IF(J23="Done","Done",IF(L23>0,"Waiting on "&L23,IF(J23="Not started","Ready",J23))) -> Done | L23: =IF(E23="",0,SUMPRODUCT(ISNUMBER(SEARCH(","&$A$5:$A$50&",",","&SUBSTITUTE(E23," ","")&","))*($J$5:$J$50<>"Done"))) -> 0 | M23: =IFERROR(""&INDEX(StatusData!$C:$C,MATCH($A23,StatusData!$A:$A,0)),"") -> Claude Sonnet 5 | N23: =IF(M23="","",IFERROR(IF(INDEX(Models!$E$5:$G$19,MATCH(M23,Models!$A$5:$A$19,0),VALUE(RIGHT(D23,1)))="Yes","OK",IF(INDEX(Models!$E$5:$G$19,MATCH(M23,Models!$A$5:$A$19,0),VALUE(RIGHT(D23,1)))="Caution","Needs T3 review","NOT ALLOWED")),"Unknown model")) -> OK | O23: =IFERROR(""&INDEX(StatusData!$D:$D,MATCH($A23,StatusData!$A:$A,0)),"") -> Claude Opus 5.5 | P23: =IFERROR(""&INDEX(StatusData!$E:$E,MATCH($A23,StatusData!$A:$A,0)),"") -> 292da21 | Q23: =IFERROR(""&INDEX(StatusData!$F:$F,MATCH($A23,StatusData!$A:$A,0)),"") -> 2026-09-24: Review-fix round 2: fixed race where load_device_identity could rename another writer's in-progress key/passphrase files; load_device_identity now read-only, cleanup moved into ensure_device_identity under the lock. Also split lock acquire-timeout from stale-steal threshold. 986 passed / 10 pre-existing failed / 2 skipped. | R23: =IF(K23="Ready",B23,"")
A24: P2-2 | B24: 2 | C24: Office admin key, membership records, signatures | D24: T3 | E24: P2-1 | G24: Yes – Fable 5.1 / Opus 5.5 | H24: =INDEX(Models!$C$26:$C$28,MATCH(D24,Models!$A$26:$A$28,0)) -> Claude Fable 5.1 or Opus 5.5 | I24: =INDEX(Models!$D$26:$D$28,MATCH(D24,Models!$A$26:$A$28,0)) -> Not allowed (owner decision) | J24: =IFERROR(IF(INDEX(StatusData!$B:$B,MATCH($A24,StatusData!$A:$A,0))="","Not started",""&INDEX(StatusData!$B:$B,MATCH($A24,StatusData!$A:$A,0))),"Not started") -> Done | K24: =IF(J24="Done","Done",IF(L24>0,"Waiting on "&L24,IF(J24="Not started","Ready",J24))) -> Done | L24: =IF(E24="",0,SUMPRODUCT(ISNUMBER(SEARCH(","&$A$5:$A$50&",",","&SUBSTITUTE(E24," ","")&","))*($J$5:$J$50<>"Done"))) -> 0 | M24: =IFERROR(""&INDEX(StatusData!$C:$C,MATCH($A24,StatusData!$A:$A,0)),"") -> Claude Opus 5.5 | N24: =IF(M24="","",IFERROR(IF(INDEX(Models!$E$5:$G$19,MATCH(M24,Models!$A$5:$A$19,0),VALUE(RIGHT(D24,1)))="Yes","OK",IF(INDEX(Models!$E$5:$G$19,MATCH(M24,Models!$A$5:$A$19,0),VALUE(RIGHT(D24,1)))="Caution","Needs T3 review","NOT ALLOWED")),"Unknown model")) -> OK | O24: =IFERROR(""&INDEX(StatusData!$D:$D,MATCH($A24,StatusData!$A:$A,0)),"") -> Claude Opus 5.5 | P24: =IFERROR(""&INDEX(StatusData!$E:$E,MATCH($A24,StatusData!$A:$A,0)),"") -> 0820ee8 | Q24: =IFERROR(""&INDEX(StatusData!$F:$F,MATCH($A24,StatusData!$A:$A,0)),"") -> 2026-09-24: Review fixes: revoke is final + letter/cert immutable in store_record; readers always verify; claim_admin check inside tx, refuses caller tx; 63 tests; suite 1049 passed / 10 pre-existing failed / 2 skipped | R24: =IF(K24="Ready",B24,"")
A25: P2-3 | B25: 2 | C25: Mutual-TLS transport + framing | D25: T3 | E25: P2-1 | G25: Yes – Fable 5.1 / Opus 5.5 | H25: =INDEX(Models!$C$26:$C$28,MATCH(D25,Models!$A$26:$A$28,0)) -> Claude Fable 5.1 or Opus 5.5 | I25: =INDEX(Models!$D$26:$D$28,MATCH(D25,Models!$A$26:$A$28,0)) -> Not allowed (owner decision) | J25: =IFERROR(IF(INDEX(StatusData!$B:$B,MATCH($A25,StatusData!$A:$A,0))="","Not started",""&INDEX(StatusData!$B:$B,MATCH($A25,StatusData!$A:$A,0))),"Not started") -> Done | K25: =IF(J25="Done","Done",IF(L25>0,"Waiting on "&L25,IF(J25="Not started","Ready",J25))) -> Done | L25: =IF(E25="",0,SUMPRODUCT(ISNUMBER(SEARCH(","&$A$5:$A$50&",",","&SUBSTITUTE(E25," ","")&","))*($J$5:$J$50<>"Done"))) -> 0 | M25: =IFERROR(""&INDEX(StatusData!$C:$C,MATCH($A25,StatusData!$A:$A,0)),"") -> Claude Opus 5.5 | N25: =IF(M25="","",IFERROR(IF(INDEX(Models!$E$5:$G$19,MATCH(M25,Models!$A$5:$A$19,0),VALUE(RIGHT(D25,1)))="Yes","OK",IF(INDEX(Models!$E$5:$G$19,MATCH(M25,Models!$A$5:$A$19,0),VALUE(RIGHT(D25,1)))="Caution","Needs T3 review","NOT ALLOWED")),"Unknown model")) -> OK | O25: =IFERROR(""&INDEX(StatusData!$D:$D,MATCH($A25,StatusData!$A:$A,0)),"") -> Claude Opus 5.5 | P25: =IFERROR(""&INDEX(StatusData!$E:$E,MATCH($A25,StatusData!$A:$A,0)),"") -> 75e98e0 | Q25: =IFERROR(""&INDEX(StatusData!$F:$F,MATCH($A25,StatusData!$A:$A,0)),"") -> 2026-09-24: Review fixes: session slots only after member check + pending-handshake caps, recv(wait=), sink/RecursionError/empty-chunk fixes; 32 transport tests; full suite 1081 passed / 10 pre-existing failures | R25: =IF(K25="Ready",B25,"")
A26: P2-4 | B26: 2 | C26: Pairing with 6-digit code (SPAKE2) | D26: T3 | E26: P2-2,P2-3 | G26: Yes – Fable 5.1 / Opus 5.5 | H26: =INDEX(Models!$C$26:$C$28,MATCH(D26,Models!$A$26:$A$28,0)) -> Claude Fable 5.1 or Opus 5.5 | I26: =INDEX(Models!$D$26:$D$28,MATCH(D26,Models!$A$26:$A$28,0)) -> Not allowed (owner decision) | J26: =IFERROR(IF(INDEX(StatusData!$B:$B,MATCH($A26,StatusData!$A:$A,0))="","Not started",""&INDEX(StatusData!$B:$B,MATCH($A26,StatusData!$A:$A,0))),"Not started") -> Done | K26: =IF(J26="Done","Done",IF(L26>0,"Waiting on "&L26,IF(J26="Not started","Ready",J26))) -> Done | L26: =IF(E26="",0,SUMPRODUCT(ISNUMBER(SEARCH(","&$A$5:$A$50&",",","&SUBSTITUTE(E26," ","")&","))*($J$5:$J$50<>"Done"))) -> 0 | M26: =IFERROR(""&INDEX(StatusData!$C:$C,MATCH($A26,StatusData!$A:$A,0)),"") -> Claude Opus 5.5 | N26: =IF(M26="","",IFERROR(IF(INDEX(Models!$E$5:$G$19,MATCH(M26,Models!$A$5:$A$19,0),VALUE(RIGHT(D26,1)))="Yes","OK",IF(INDEX(Models!$E$5:$G$19,MATCH(M26,Models!$A$5:$A$19,0),VALUE(RIGHT(D26,1)))="Caution","Needs T3 review","NOT ALLOWED")),"Unknown model")) -> OK | O26: =IFERROR(""&INDEX(StatusData!$D:$D,MATCH($A26,StatusData!$A:$A,0)),"") -> Claude Opus 5.5 | P26: =IFERROR(""&INDEX(StatusData!$E:$E,MATCH($A26,StatusData!$A:$A,0)),"") -> d2627e2 | Q26: =IFERROR(""&INDEX(StatusData!$F:$F,MATCH($A26,StatusData!$A:$A,0)),"") -> 2026-09-24: Review fixes: no second join in the join/close gap (close before freeing slot; close ends any session), stall warning, _install order; 38 pairing tests pass; full suite 1143 passed / 10 pre-existing failures | R26: =IF(K26="Ready",B26,"")
A27: P2-5 | B27: 2 | C27: Discovery v3, address book, gossip | D27: T2 | E27: P2-3 | G27: No | H27: =INDEX(Models!$C$26:$C$28,MATCH(D27,Models!$A$26:$A$28,0)) -> Claude Sonnet 5 | I27: =INDEX(Models!$D$26:$D$28,MATCH(D27,Models!$A$26:$A$28,0)) -> Gemini 3.8 Flash, 3.1 Pro, 3.7 Flash (3.6 Flash / 3 Flash / 2.5 Pro only with review) | J27: =IFERROR(IF(INDEX(StatusData!$B:$B,MATCH($A27,StatusData!$A:$A,0))="","Not started",""&INDEX(StatusData!$B:$B,MATCH($A27,StatusData!$A:$A,0))),"Not started") -> Done | K27: =IF(J27="Done","Done",IF(L27>0,"Waiting on "&L27,IF(J27="Not started","Ready",J27))) -> Done | L27: =IF(E27="",0,SUMPRODUCT(ISNUMBER(SEARCH(","&$A$5:$A$50&",",","&SUBSTITUTE(E27," ","")&","))*($J$5:$J$50<>"Done"))) -> 0 | M27: =IFERROR(""&INDEX(StatusData!$C:$C,MATCH($A27,StatusData!$A:$A,0)),"") -> Gemini 3.8 Flash | N27: =IF(M27="","",IFERROR(IF(INDEX(Models!$E$5:$G$19,MATCH(M27,Models!$A$5:$A$19,0),VALUE(RIGHT(D27,1)))="Yes","OK",IF(INDEX(Models!$E$5:$G$19,MATCH(M27,Models!$A$5:$A$19,0),VALUE(RIGHT(D27,1)))="Caution","Needs T3 review","NOT ALLOWED")),"Unknown model")) -> OK | O27: =IFERROR(""&INDEX(StatusData!$D:$D,MATCH($A27,StatusData!$A:$A,0)),"") -> Claude Opus 5.5 | P27: =IFERROR(""&INDEX(StatusData!$E:$E,MATCH($A27,StatusData!$A:$A,0)),"") -> 31dc65f | Q27: =IFERROR(""&INDEX(StatusData!$F:$F,MATCH($A27,StatusData!$A:$A,0)),"") -> 2026-09-24: Review fixes & refinements: listen=False mode, ephemeral unicast reply, sightings capping (500), open_db warning, gossip IP validation; 28 tests pass | R27: =IF(K27="Ready",B27,"")
A28: P2-6 | B28: 2 | C28: Snapshot service + joiner install | D28: T2 | E28: P2-3,P2-4 | G28: Yes – Fable 5.1 / Opus 5.5 | H28: =INDEX(Models!$C$26:$C$28,MATCH(D28,Models!$A$26:$A$28,0)) -> Claude Sonnet 5 | I28: =INDEX(Models!$D$26:$D$28,MATCH(D28,Models!$A$26:$A$28,0)) -> Gemini 3.8 Flash, 3.1 Pro, 3.7 Flash (3.6 Flash / 3 Flash / 2.5 Pro only with review) | J28: =IFERROR(IF(INDEX(StatusData!$B:$B,MATCH($A28,StatusData!$A:$A,0))="","Not started",""&INDEX(StatusData!$B:$B,MATCH($A28,StatusData!$A:$A,0))),"Not started") -> Done | K28: =IF(J28="Done","Done",IF(L28>0,"Waiting on "&L28,IF(J28="Not started","Ready",J28))) -> Done | L28: =IF(E28="",0,SUMPRODUCT(ISNUMBER(SEARCH(","&$A$5:$A$50&",",","&SUBSTITUTE(E28," ","")&","))*($J$5:$J$50<>"Done"))) -> 0 | M28: =IFERROR(""&INDEX(StatusData!$C:$C,MATCH($A28,StatusData!$A:$A,0)),"") -> Gemini 3.8 Flash | N28: =IF(M28="","",IFERROR(IF(INDEX(Models!$E$5:$G$19,MATCH(M28,Models!$A$5:$A$19,0),VALUE(RIGHT(D28,1)))="Yes","OK",IF(INDEX(Models!$E$5:$G$19,MATCH(M28,Models!$A$5:$A$19,0),VALUE(RIGHT(D28,1)))="Caution","Needs T3 review","NOT ALLOWED")),"Unknown model")) -> OK | O28: =IFERROR(""&INDEX(StatusData!$D:$D,MATCH($A28,StatusData!$A:$A,0)),"") -> Claude Opus 5.5 | P28: =IFERROR(""&INDEX(StatusData!$E:$E,MATCH($A28,StatusData!$A:$A,0)),"") -> e15c420 | Q28: =IFERROR(""&INDEX(StatusData!$F:$F,MATCH($A28,StatusData!$A:$A,0)),"") -> 2026-09-24: Snapshot mTLS service, export, verification, atomic joiner install with backups (master.db last); 11 tests passed. Open items for P2-7/P2-8/P3-5 recorded in blueprint §9 P2-6 notes (P2-7 must start the snapshot server). | R28: =IF(K28="Ready",B28,"")
A29: P2-7 | B29: 2 | C29: UI: Join wizard, Add workstation, Members, Remove, Hand over admin | D29: T2 | E29: P2-4,P2-6 | G29: No | H29: =INDEX(Models!$C$26:$C$28,MATCH(D29,Models!$A$26:$A$28,0)) -> Claude Sonnet 5 | I29: =INDEX(Models!$D$26:$D$28,MATCH(D29,Models!$A$26:$A$28,0)) -> Gemini 3.8 Flash, 3.1 Pro, 3.7 Flash (3.6 Flash / 3 Flash / 2.5 Pro only with review) | J29: =IFERROR(IF(INDEX(StatusData!$B:$B,MATCH($A29,StatusData!$A:$A,0))="","Not started",""&INDEX(StatusData!$B:$B,MATCH($A29,StatusData!$A:$A,0))),"Not started") -> Done | K29: =IF(J29="Done","Done",IF(L29>0,"Waiting on "&L29,IF(J29="Not started","Ready",J29))) -> Done | L29: =IF(E29="",0,SUMPRODUCT(ISNUMBER(SEARCH(","&$A$5:$A$50&",",","&SUBSTITUTE(E29," ","")&","))*($J$5:$J$50<>"Done"))) -> 0 | M29: =IFERROR(""&INDEX(StatusData!$C:$C,MATCH($A29,StatusData!$A:$A,0)),"") -> Claude Sonnet 5 | N29: =IF(M29="","",IFERROR(IF(INDEX(Models!$E$5:$G$19,MATCH(M29,Models!$A$5:$A$19,0),VALUE(RIGHT(D29,1)))="Yes","OK",IF(INDEX(Models!$E$5:$G$19,MATCH(M29,Models!$A$5:$A$19,0),VALUE(RIGHT(D29,1)))="Caution","Needs T3 review","NOT ALLOWED")),"Unknown model")) -> OK | O29: =IFERROR(""&INDEX(StatusData!$D:$D,MATCH($A29,StatusData!$A:$A,0)),"") -> Claude Opus 5.5 | P29: =IFERROR(""&INDEX(StatusData!$E:$E,MATCH($A29,StatusData!$A:$A,0)),"") -> d8af4c1 | Q29: =IFERROR(""&INDEX(StatusData!$F:$F,MATCH($A29,StatusData!$A:$A,0)),"") -> 2026-09-25: UI: Join wizard, Add workstation, Members, Remove, Hand over/Become admin. New sync_office.py (create_new_office, join_office, AddWorkstationSession) + sync_admin.hand_over_admin. Fixed main.py office_mode start-up gap and QTimer.singleShot cross-thread bug (Qt signals) across both first-run pages. 20 new tests (test_sync_office.py, test_sync_office_ui.py) + 5 hand_over_admin tests; full suite 1279 passed / 16 pre-existing+expected failed. | R29: =IF(K29="Ready",B29,"")
... A31: P3-0 | B31: 3 | C31: Multi-node test harness + convergence tests (written first) | D31: T2 | E31: P2-3 | G31: Yes – Fable 5.1 / Opus 5.5 | H31: =INDEX(Models!$C$26:$C$28,MATCH(D31,Models!$A$26:$A$28,0)) -> Claude Sonnet 5 | I31: =INDEX(Models!$D$26:$D$28,MATCH(D31,Models!$A$26:$A$28,0)) -> Gemini 3.8 Flash, 3.1 Pro, 3.7 Flash (3.6 Flash / 3 Flash / 2.5 Pro only with review) | J31: =IFERROR(IF(INDEX(StatusData!$B:$B,MATCH($A31,StatusData!$A:$A,0))="","Not started",""&INDEX(StatusData!$B:$B,MATCH($A31,StatusData!$A:$A,0))),"Not started") -> Done | K31: =IF(J31="Done","Done",IF(L31>0,"Waiting on "&L31,IF(J31="Not started","Ready",J31))) -> Done | L31: =IF(E31="",0,SUMPRODUCT(ISNUMBER(SEARCH(","&$A$5:$A$50&",",","&SUBSTITUTE(E31," ","")&","))*($J$5:$J$50<>"Done"))) -> 0 | M31: =IFERROR(""&INDEX(StatusData!$C:$C,MATCH($A31,StatusData!$A:$A,0)),"") -> Gemini 3.8 Flash | N31: =IF(M31="","",IFERROR(IF(INDEX(Models!$E$5:$G$19,MATCH(M31,Models!$A$5:$A$19,0),VALUE(RIGHT(D31,1)))="Yes","OK",IF(INDEX(Models!$E$5:$G$19,MATCH(M31,Models!$A$5:$A$19,0),VALUE(RIGHT(D31,1)))="Caution","Needs T3 review","NOT ALLOWED")),"Unknown model")) -> OK | O31: =IFERROR(""&INDEX(StatusData!$D:$D,MATCH($A31,StatusData!$A:$A,0)),"") -> Claude Opus 5.5 | P31: =IFERROR(""&INDEX(StatusData!$E:$E,MATCH($A31,StatusData!$A:$A,0)),"") -> be84d98 | Q31: =IFERROR(""&INDEX(StatusData!$F:$F,MATCH($A31,StatusData!$A:$A,0)),"") -> 2026-09-24: Review round 3 fixes: write() routes via SeraDatabase._connect for sealer hooks, dynamic time in (b), (d) conflict row on n0 only, (e) partitioned single batch & vector freeze check, stringified FK translation in digest; 7 harness passed, 6 convergence failed as expected, 1185 passed in full suite | R31: =IF(K31="Ready",B31,"")
A32: P3-1 | B32: 3 | C32: Table / setting classification registry sync_schema.py | D32: T2 | G32: Yes – Fable 5.1 / Opus 5.5 | H32: =INDEX(Models!$C$26:$C$28,MATCH(D32,Models!$A$26:$A$28,0)) -> Claude Sonnet 5 | I32: =INDEX(Models!$D$26:$D$28,MATCH(D32,Models!$A$26:$A$28,0)) -> Gemini 3.8 Flash, 3.1 Pro, 3.7 Flash (3.6 Flash / 3 Flash / 2.5 Pro only with review) | J32: =IFERROR(IF(INDEX(StatusData!$B:$B,MATCH($A32,StatusData!$A:$A,0))="","Not started",""&INDEX(StatusData!$B:$B,MATCH($A32,StatusData!$A:$A,0))),"Not started") -> Done | K32: =IF(J32="Done","Done",IF(L32>0,"Waiting on "&L32,IF(J32="Not started","Ready",J32))) -> Done | L32: =IF(E32="",0,SUMPRODUCT(ISNUMBER(SEARCH(","&$A$5:$A$50&",",","&SUBSTITUTE(E32," ","")&","))*($J$5:$J$50<>"Done"))) -> 0 | M32: =IFERROR(""&INDEX(StatusData!$C:$C,MATCH($A32,StatusData!$A:$A,0)),"") -> Claude Sonnet 5 | N32: =IF(M32="","",IFERROR(IF(INDEX(Models!$E$5:$G$19,MATCH(M32,Models!$A$5:$A$19,0),VALUE(RIGHT(D32,1)))="Yes","OK",IF(INDEX(Models!$E$5:$G$19,MATCH(M32,Models!$A$5:$A$19,0),VALUE(RIGHT(D32,1)))="Caution","Needs T3 review","NOT ALLOWED")),"Unknown model")) -> OK | O32: =IFERROR(""&INDEX(StatusData!$D:$D,MATCH($A32,StatusData!$A:$A,0)),"") -> Claude Opus 5.5 | P32: =IFERROR(""&INDEX(StatusData!$E:$E,MATCH($A32,StatusData!$A:$A,0)),"") -> 882d054 | Q32: =IFERROR(""&INDEX(StatusData!$F:$F,MATCH($A32,StatusData!$A:$A,0)),"") -> 2026-09-24: Round 2: client_raw_containers reverted to local (whole-row lww would have caused certain data loss via re_resolve_all_tracker_dumps' DELETE+rebuild under P3-3/P3-4 tombstone rules). New pending_creation client_container_notes TableSpec added for staff notes, lww, table itself not yet built (flagged for P3-2). 22 new schema tests + 2 database tests pass; full suite at baseline. | R32: =IF(K32="Ready",B32,"")
A33: P3-2 | B33: 3 | C33: gid columns, back-fill, deterministic seed gids, _sync_* tables | D33: T2 | E33: P3-1 | G33: No | H33: =INDEX(Models!$C$26:$C$28,MATCH(D33,Models!$A$26:$A$28,0)) -> Claude Sonnet 5 | I33: =INDEX(Models!$D$26:$D$28,MATCH(D33,Models!$A$26:$A$28,0)) -> Gemini 3.8 Flash, 3.1 Pro, 3.7 Flash (3.6 Flash / 3 Flash / 2.5 Pro only with review) | J33: =IFERROR(IF(INDEX(StatusData!$B:$B,MATCH($A33,StatusData!$A:$A,0))="","Not started",""&INDEX(StatusData!$B:$B,MATCH($A33,StatusData!$A:$A,0))),"Not started") -> Done | K33: =IF(J33="Done","Done",IF(L33>0,"Waiting on "&L33,IF(J33="Not started","Ready",J33))) -> Done | L33: =IF(E33="",0,SUMPRODUCT(ISNUMBER(SEARCH(","&$A$5:$A$50&",",","&SUBSTITUTE(E33," ","")&","))*($J$5:$J$50<>"Done"))) -> 0 | M33: =IFERROR(""&INDEX(StatusData!$C:$C,MATCH($A33,StatusData!$A:$A,0)),"") -> Gemini 3.8 Flash | N33: =IF(M33="","",IFERROR(IF(INDEX(Models!$E$5:$G$19,MATCH(M33,Models!$A$5:$A$19,0),VALUE(RIGHT(D33,1)))="Yes","OK",IF(INDEX(Models!$E$5:$G$19,MATCH(M33,Models!$A$5:$A$19,0),VALUE(RIGHT(D33,1)))="Caution","Needs T3 review","NOT ALLOWED")),"Unknown model")) -> OK | O33: =IFERROR(""&INDEX(StatusData!$D:$D,MATCH($A33,StatusData!$A:$A,0)),"") -> Claude Opus 5.5 | P33: =IFERROR(""&INDEX(StatusData!$E:$E,MATCH($A33,StatusData!$A:$A,0)),"") -> 067828b | Q33: =IFERROR(""&INDEX(StatusData!$F:$F,MATCH($A33,StatusData!$A:$A,0)),"") -> 2026-09-25: B1 fixed, all should-fix items addressed, fresh INI seeding harmonized; 104 passed / 0 failed | R33: =IF(K33="Ready",B33,"")
A34: P3-3 | B34: 3 | C34: Capture triggers + sealer + hybrid logical clock | D34: T3 | E34: P3-2 | G34: Yes – Fable 5.1 / Opus 5.5 | H34: =INDEX(Models!$C$26:$C$28,MATCH(D34,Models!$A$26:$A$28,0)) -> Claude Fable 5.1 or Opus 5.5 | I34: =INDEX(Models!$D$26:$D$28,MATCH(D34,Models!$A$26:$A$28,0)) -> Not allowed (owner decision) | J34: =IFERROR(IF(INDEX(StatusData!$B:$B,MATCH($A34,StatusData!$A:$A,0))="","Not started",""&INDEX(StatusData!$B:$B,MATCH($A34,StatusData!$A:$A,0))),"Not started") -> Done | K34: =IF(J34="Done","Done",IF(L34>0,"Waiting on "&L34,IF(J34="Not started","Ready",J34))) -> Done | L34: =IF(E34="",0,SUMPRODUCT(ISNUMBER(SEARCH(","&$A$5:$A$50&",",","&SUBSTITUTE(E34," ","")&","))*($J$5:$J$50<>"Done"))) -> 0 | M34: =IFERROR(""&INDEX(StatusData!$C:$C,MATCH($A34,StatusData!$A:$A,0)),"") -> Claude Opus 5.5 | N34: =IF(M34="","",IFERROR(IF(INDEX(Models!$E$5:$G$19,MATCH(M34,Models!$A$5:$A$19,0),VALUE(RIGHT(D34,1)))="Yes","OK",IF(INDEX(Models!$E$5:$G$19,MATCH(M34,Models!$A$5:$A$19,0),VALUE(RIGHT(D34,1)))="Caution","Needs T3 review","NOT ALLOWED")),"Unknown model")) -> OK | O34: =IFERROR(""&INDEX(StatusData!$D:$D,MATCH($A34,StatusData!$A:$A,0)),"") -> Claude Opus 5.5 | P34: =IFERROR(""&INDEX(StatusData!$E:$E,MATCH($A34,StatusData!$A:$A,0)),"") -> f34baaa | Q34: =IFERROR(""&INDEX(StatusData!$F:$F,MATCH($A34,StatusData!$A:$A,0)),"") -> 2026-09-25: Review fixes + owner option A: per-stream seq high-water mark in keys/sync_seq.json (raised after commit; unreadable file stops sealing); 86 tests pass; full suite 1366/16 (known) | R34: =IF(K34="Ready",B34,"")
A35: P3-4 | B35: 3 | C35: Apply engine (field LWW, tombstones, FK translation, parking, admin signatures) | D35: T3 | E35: P3-3 | G35: Yes – Fable 5.1 / Opus 5.5 | H35: =INDEX(Models!$C$26:$C$28,MATCH(D35,Models!$A$26:$A$28,0)) -> Claude Fable 5.1 or Opus 5.5 | I35: =INDEX(Models!$D$26:$D$28,MATCH(D35,Models!$A$26:$A$28,0)) -> Not allowed (owner decision) | J35: =IFERROR(IF(INDEX(StatusData!$B:$B,MATCH($A35,StatusData!$A:$A,0))="","Not started",""&INDEX(StatusData!$B:$B,MATCH($A35,StatusData!$A:$A,0))),"Not started") -> Done | K35: =IF(J35="Done","Done",IF(L35>0,"Waiting on "&L35,IF(J35="Not started","Ready",J35))) -> Done | L35: =IF(E35="",0,SUMPRODUCT(ISNUMBER(SEARCH(","&$A$5:$A$50&",",","&SUBSTITUTE(E35," ","")&","))*($J$5:$J$50<>"Done"))) -> 0 | M35: =IFERROR(""&INDEX(StatusData!$C:$C,MATCH($A35,StatusData!$A:$A,0)),"") -> Claude Opus 5.5 | N35: =IF(M35="","",IFERROR(IF(INDEX(Models!$E$5:$G$19,MATCH(M35,Models!$A$5:$A$19,0),VALUE(RIGHT(D35,1)))="Yes","OK",IF(INDEX(Models!$E$5:$G$19,MATCH(M35,Models!$A$5:$A$19,0),VALUE(RIGHT(D35,1)))="Caution","Needs T3 review","NOT ALLOWED")),"Unknown model")) -> OK | O35: =IFERROR(""&INDEX(StatusData!$D:$D,MATCH($A35,StatusData!$A:$A,0)),"") -> Claude Opus 5.5 | P35: =IFERROR(""&INDEX(StatusData!$E:$E,MATCH($A35,StatusData!$A:$A,0)),"") -> 48c2335 | Q35: =IFERROR(""&INDEX(StatusData!$F:$F,MATCH($A35,StatusData!$A:$A,0)),"") -> 2026-09-25: New sync_apply.py apply engine (LWW, tombstones incl. newer re-create for natural keys, parking, admin sigs, natural-key + PAN merge sent as merge changes) + review fixes; 58 tests pass (2 fail only with uncommitted P3-6 resequence in tree); full suite 1421/16 known | R35: =IF(K35="Ready",B35,"")
A36: P3-5 | B36: 3 | C36: Sync session protocol, forwarding, poke, scheduler | D36: T3 | E36: P3-4,P2-5 | G36: Yes – Fable 5.1 / Opus 5.5 | H36: =INDEX(Models!$C$26:$C$28,MATCH(D36,Models!$A$26:$A$28,0)) -> Claude Fable 5.1 or Opus 5.5 | I36: =INDEX(Models!$D$26:$D$28,MATCH(D36,Models!$A$26:$A$28,0)) -> Not allowed (owner decision) | J36: =IFERROR(IF(INDEX(StatusData!$B:$B,MATCH($A36,StatusData!$A:$A,0))="","Not started",""&INDEX(StatusData!$B:$B,MATCH($A36,StatusData!$A:$A,0))),"Not started") -> Done | K36: =IF(J36="Done","Done",IF(L36>0,"Waiting on "&L36,IF(J36="Not started","Ready",J36))) -> Done | L36: =IF(E36="",0,SUMPRODUCT(ISNUMBER(SEARCH(","&$A$5:$A$50&",",","&SUBSTITUTE(E36," ","")&","))*($J$5:$J$50<>"Done"))) -> 0 | M36: =IFERROR(""&INDEX(StatusData!$C:$C,MATCH($A36,StatusData!$A:$A,0)),"") -> Claude Opus 5.5 | N36: =IF(M36="","",IFERROR(IF(INDEX(Models!$E$5:$G$19,MATCH(M36,Models!$A$5:$A$19,0),VALUE(RIGHT(D36,1)))="Yes","OK",IF(INDEX(Models!$E$5:$G$19,MATCH(M36,Models!$A$5:$A$19,0),VALUE(RIGHT(D36,1)))="Caution","Needs T3 review","NOT ALLOWED")),"Unknown model")) -> OK | O36: =IFERROR(""&INDEX(StatusData!$D:$D,MATCH($A36,StatusData!$A:$A,0)),"") -> Claude Opus 5.5 | P36: =IFERROR(""&INDEX(StatusData!$E:$E,MATCH($A36,StatusData!$A:$A,0)),"") -> 3fd8004 | Q36: =IFERROR(""&INDEX(StatusData!$F:$F,MATCH($A36,StatusData!$A:$A,0)),"") -> 2026-09-25: New sync_engine.py (HELLO/members/CHANGES+ACK/BYE, forwarding, poke, 20s scheduler) + harness wiring; P3-0 (a)-(f) pass; 29 new tests; full suite 1467 pass / 11 pre-existing fail | R36: =IF(K36="Ready",B36,"")
A37: P3-6 | B37: 3 | C37: Make start-up maintenance admin-only / id-independent (F12, F13) | D37: T2 | E37: P3-2 | G37: Yes – Fable 5.1 / Opus 5.5 | H37: =INDEX(Models!$C$26:$C$28,MATCH(D37,Models!$A$26:$A$28,0)) -> Claude Sonnet 5 | I37: =INDEX(Models!$D$26:$D$28,MATCH(D37,Models!$A$26:$A$28,0)) -> Gemini 3.8 Flash, 3.1 Pro, 3.7 Flash (3.6 Flash / 3 Flash / 2.5 Pro only with review) | J37: =IFERROR(IF(INDEX(StatusData!$B:$B,MATCH($A37,StatusData!$A:$A,0))="","Not started",""&INDEX(StatusData!$B:$B,MATCH($A37,StatusData!$A:$A,0))),"Not started") -> Done | K37: =IF(J37="Done","Done",IF(L37>0,"Waiting on "&L37,IF(J37="Not started","Ready",J37))) -> Done | L37: =IF(E37="",0,SUMPRODUCT(ISNUMBER(SEARCH(","&$A$5:$A$50&",",","&SUBSTITUTE(E37," ","")&","))*($J$5:$J$50<>"Done"))) -> 0 | M37: =IFERROR(""&INDEX(StatusData!$C:$C,MATCH($A37,StatusData!$A:$A,0)),"") -> Gemini 3.8 Flash | N37: =IF(M37="","",IFERROR(IF(INDEX(Models!$E$5:$G$19,MATCH(M37,Models!$A$5:$A$19,0),VALUE(RIGHT(D37,1)))="Yes","OK",IF(INDEX(Models!$E$5:$G$19,MATCH(M37,Models!$A$5:$A$19,0),VALUE(RIGHT(D37,1)))="Caution","Needs T3 review","NOT ALLOWED")),"Unknown model")) -> OK | O37: =IFERROR(""&INDEX(StatusData!$D:$D,MATCH($A37,StatusData!$A:$A,0)),"") -> Claude Opus 5.5 | P37: =IFERROR(""&INDEX(StatusData!$E:$E,MATCH($A37,StatusData!$A:$A,0)),"") -> 27bfc64 | Q37: =IFERROR(""&INDEX(StatusData!$F:$F,MATCH($A37,StatusData!$A:$A,0)),"") -> 2026-09-25: Opus review fixes: gated apply resequence, hardened acceptance test; 295 sync tests pass, full suite 1432/17/3 | R37: =IF(K37="Ready",B37,"")
A38: P3-7 | B38: 3 | C38: Shadow mode: capture check, replica convergence, digests | D38: T2 | E38: P3-5 | G38: Yes – Fable 5.1 / Opus 5.5 | H38: =INDEX(Models!$C$26:$C$28,MATCH(D38,Models!$A$26:$A$28,0)) -> Claude Sonnet 5 | I38: =INDEX(Models!$D$26:$D$28,MATCH(D38,Models!$A$26:$A$28,0)) -> Gemini 3.8 Flash, 3.1 Pro, 3.7 Flash (3.6 Flash / 3 Flash / 2.5 Pro only with review) | J38: =IFERROR(IF(INDEX(StatusData!$B:$B,MATCH($A38,StatusData!$A:$A,0))="","Not started",""&INDEX(StatusData!$B:$B,MATCH($A38,StatusData!$A:$A,0))),"Not started") -> Done | K38: =IF(J38="Done","Done",IF(L38>0,"Waiting on "&L38,IF(J38="Not started","Ready",J38))) -> Done | L38: =IF(E38="",0,SUMPRODUCT(ISNUMBER(SEARCH(","&$A$5:$A$50&",",","&SUBSTITUTE(E38," ","")&","))*($J$5:$J$50<>"Done"))) -> 0 | M38: =IFERROR(""&INDEX(StatusData!$C:$C,MATCH($A38,StatusData!$A:$A,0)),"") -> Claude Sonnet 5 | N38: =IF(M38="","",IFERROR(IF(INDEX(Models!$E$5:$G$19,MATCH(M38,Models!$A$5:$A$19,0),VALUE(RIGHT(D38,1)))="Yes","OK",IF(INDEX(Models!$E$5:$G$19,MATCH(M38,Models!$A$5:$A$19,0),VALUE(RIGHT(D38,1)))="Caution","Needs T3 review","NOT ALLOWED")),"Unknown model")) -> OK | O38: =IFERROR(""&INDEX(StatusData!$D:$D,MATCH($A38,StatusData!$A:$A,0)),"") -> Claude Opus 5.5 | P38: =IFERROR(""&INDEX(StatusData!$E:$E,MATCH($A38,StatusData!$A:$A,0)),"") -> a897eb5 | Q38: =IFERROR(""&INDEX(StatusData!$F:$F,MATCH($A38,StatusData!$A:$A,0)),"") -> 2026-09-25: 2026-09-25: review-fix round 1 (Opus): capture_check now replays only own-origin changes (was replaying forwarded remote copies too, failing on any PC that had received anything); enable_shadow_mode refuses when already on (silent permanent data loss). 2 new regression tests; 17 sync_shadow tests pass; full suite 1536 passed / 11 pre-existing failed / 3 skipped | R38: =IF(K38="Ready",B38,"")
A39: P3-8 | B39: 3 | C39: UI refresh by table + Sera Sync panel status | D39: T2 | E39: P3-5 | G39: No | H39: =INDEX(Models!$C$26:$C$28,MATCH(D39,Models!$A$26:$A$28,0)) -> Claude Sonnet 5 | I39: =INDEX(Models!$D$26:$D$28,MATCH(D39,Models!$A$26:$A$28,0)) -> Gemini 3.8 Flash, 3.1 Pro, 3.7 Flash (3.6 Flash / 3 Flash / 2.5 Pro only with review) | J39: =IFERROR(IF(INDEX(StatusData!$B:$B,MATCH($A39,StatusData!$A:$A,0))="","Not started",""&INDEX(StatusData!$B:$B,MATCH($A39,StatusData!$A:$A,0))),"Not started") -> Done | K39: =IF(J39="Done","Done",IF(L39>0,"Waiting on "&L39,IF(J39="Not started","Ready",J39))) -> Done | L39: =IF(E39="",0,SUMPRODUCT(ISNUMBER(SEARCH(","&$A$5:$A$50&",",","&SUBSTITUTE(E39," ","")&","))*($J$5:$J$50<>"Done"))) -> 0 | M39: =IFERROR(""&INDEX(StatusData!$C:$C,MATCH($A39,StatusData!$A:$A,0)),"") -> Claude Sonnet 5 | N39: =IF(M39="","",IFERROR(IF(INDEX(Models!$E$5:$G$19,MATCH(M39,Models!$A$5:$A$19,0),VALUE(RIGHT(D39,1)))="Yes","OK",IF(INDEX(Models!$E$5:$G$19,MATCH(M39,Models!$A$5:$A$19,0),VALUE(RIGHT(D39,1)))="Caution","Needs T3 review","NOT ALLOWED")),"Unknown model")) -> OK | O39: =IFERROR(""&INDEX(StatusData!$D:$D,MATCH($A39,StatusData!$A:$A,0)),"") -> Claude Opus 5.5 | P39: =IFERROR(""&INDEX(StatusData!$E:$E,MATCH($A39,StatusData!$A:$A,0)),"") -> a897eb5 | Q39: =IFERROR(""&INDEX(StatusData!$F:$F,MATCH($A39,StatusData!$A:$A,0)),"") -> 2026-09-25: 2026-09-25: Review fixes (Opus 5.5): use_discarded_value no longer deletes conflicts on no-op (kept for the deleted-row shape sync_apply.py actually produces, resurrection not built); wired the shadow-check timer (30min) + panel 'Run now' button that run_shadow_checks docstring asked P3-8 for; needs_update banner + stalled-streams count from peer_status()/stalled_streams(); UI refresh gated to mode live; last_ok prefers peer_status(); timer cancelled on quit; 'None' shown as '(deleted)'. 68 P3-8 tests pass; full suite 1549/11/3 (11 pre-existing). | R39: =IF(K39="Ready",B39,"")
A40: P3-7a | B40: 3 | C40: Peer digest exchange for the shadow convergence check | D40: T2 | E40: P3-7 | G40: Yes – Fable 5.1 / Opus 5.5 | H40: =INDEX(Models!$C$26:$C$28,MATCH(D40,Models!$A$26:$A$28,0)) -> Claude Sonnet 5 | I40: =INDEX(Models!$D$26:$D$28,MATCH(D40,Models!$A$26:$A$28,0)) -> Gemini 3.8 Flash, 3.1 Pro, 3.7 Flash (3.6 Flash / 3 Flash / 2.5 Pro only with review) | J40: =IFERROR(IF(INDEX(StatusData!$B:$B,MATCH($A40,StatusData!$A:$A,0))="","Not started",""&INDEX(StatusData!$B:$B,MATCH($A40,StatusData!$A:$A,0))),"Not started") -> Done | K40: =IF(J40="Done","Done",IF(L40>0,"Waiting on "&L40,IF(J40="Not started","Ready",J40))) -> Done | L40: =IF(E40="",0,SUMPRODUCT(ISNUMBER(SEARCH(","&$A$5:$A$50&",",","&SUBSTITUTE(E40," ","")&","))*($J$5:$J$50<>"Done"))) -> 0 | M40: =IFERROR(""&INDEX(StatusData!$C:$C,MATCH($A40,StatusData!$A:$A,0)),"") -> Claude Sonnet 5 | N40: =IF(M40="","",IFERROR(IF(INDEX(Models!$E$5:$G$19,MATCH(M40,Models!$A$5:$A$19,0),VALUE(RIGHT(D40,1)))="Yes","OK",IF(INDEX(Models!$E$5:$G$19,MATCH(M40,Models!$A$5:$A$19,0),VALUE(RIGHT(D40,1)))="Caution","Needs T3 review","NOT ALLOWED")),"Unknown model")) -> OK | O40: =IFERROR(""&INDEX(StatusData!$D:$D,MATCH($A40,StatusData!$A:$A,0)),"") -> Claude Opus 5.5 | P40: =IFERROR(""&INDEX(StatusData!$E:$E,MATCH($A40,StatusData!$A:$A,0)),"") -> c3f91c5 | Q40: =IFERROR(""&INDEX(StatusData!$F:$F,MATCH($A40,StatusData!$A:$A,0)),"") -> 2026-09-26: Review fixes applied (all 5 non-blocking findings from both Opus 5.5 review passes): 'vectors moved'->'vectors differ' wording; malformed digest_reply now logged as skipped instead of silently ignored; _last_local_change_at no longer stamped by a remote-driven merge (_wake_poke_sender split out); at most one digest_request answered per session (extras get busy); fixed test spy that sat on the wrong side. tests/test_sync_digest_exchange.py now 10 tests, all pass. Full suite: 1604 passed / 11 failed / 3 skipped -- the standard pre-existing set only, zero new failures. | R40: =IF(K40="Ready",B40,"")
